Workbook

Sheet README
A1: Flood × onshore wind — model-v1 review workbook
A2: Canonical partial-screening release • one source-native whole-substation atom • registry activation remains deliberate
A4: Identity | B4: Value | C4: Invariant | D4: Order | E4: Sheet | F4: Purpose
A5: Cell ID | B5: flood_wind | C5: hazard × asset project-management cell | D5: 1 | E5: README | F5: Identity, status, and map
A6: Damage code | B6: FLOOD_WIND_FEMA_HAZUS_SUBSTATION_SCREENING_V1 | C6: review implementation only | D6: 2 | E6: Scope_Coverage | F6: Boundary and coverage
A7: Semantic model | B7: model v1.0 | C7: first partial numerical proposal | D7: 3 | E7: Hazus_Source | F7: Exact FEMA table transcription
A8: Documentation | B8: docs r1 | C8: governed proof trail | D8: 4 | E8: Curve | F8: Curve and interpolation examples
A9: Model grade | B9: screening_source_native_legacy_fema_proxy | C9: legacy FEMA screening sensitivity | D9: 5 | E9: Axis_Bridge | F9: Datum-safe WSE bridge
A10: Supported atom | B10: FW_HAZUS_GSU_SUBSTATION_ASSEMBLY | C10: whole substation, not a component curve | D10: 6 | E10: Failure_Units | F10: Failure-unit coverage and withholding
A11: Runtime curve count | B11: 1 | C11: exactly one source-native piecewise-linear record | D11: 7 | E11: Value_Crosswalk | F11: Value/denominator crosswalk
A12: Canonical runtime artifact | B12: FALSE | C12: must remain false | D12: 8 | E12: Old_vs_New | F12: v0.1 versus v1.0
A13: Package inclusion | B13: not_included | C13: no package or consumer pin | D13: 9 | E13: KATs | F13: Executable test inventory
A14: Scenario loss | B14: conditional | C14: same-substation value only after release | D14: 10 | E14: Source_Register | F14: Sources and transfer limits
A15: Annual/tail metrics | B15: withheld | C15: owned by downstream consumer; prerequisites unmet | D15: 11 | E15: Claim_Register | F15: Governed claims
D16: 12 | E16: Parameter_Tiers | F16: Parameter evidence tiers
D17: 13 | E17: QA | F17: Formula-driven workbook QA
A18: Decision guardrail: Hazus-MH 2.1 Table 7.9 is retained only as an explicit whole-substation screening sensitivity. Current Hazus 7.0 marks electric-power facilities mapping-only and disables those loss functions. No GSU component, turbine, collection, civil, foundation, scenario-loss, annual, or tail result is enabled by this workbook.

Sheet Scope_Coverage
A1: Scope and coverage
A2: What the v1 proposal does and does not cover
A4: Layer | B4: Subject | C4: Status | D4: Reason / boundary | E4: Value basis | F4: Exposure grain | G4: Consumer treatment
A5: Hazard | B5: Freshwater inundation contact | C5: conditional | D5: unprotected or internal post-bypass depth only | E5: n/a | F5: same substation | G5: pass exact pathway + conditions
A6: Assembly | B6: Hazus whole substation | C6: conditional numeric | D6: legacy source-native atom; not component-calibrated | E6: full direct replacement value of same substation | F6: one physical GSU/substation | G6: DR only in proposal
A7: Component | B7: GSU transformer / switchgear / controls / cables | C7: withheld not zero | D7: component repair-cost DR not supported | E7: same component value in future | F7: same component | G7: preserve null + reasons
A8: Wind plant | B8: turbines / pad transformers / collection / civil / foundation | C8: withheld not zero | D8: outside the Hazus source atom | E8: same-unit split required | F8: unit / point / line | G8: preserve null + reasons
A9: Protection | B9: barriers / elevation / sealing | C9: no multiplier | D9: handled once in delivered internal depth | E9: n/a | F9: site condition | G9: no silent credit
A10: Water quality | B10: salt / brackish / contaminated / unknown | C10: withheld | D10: outside screening domain | E10: n/a | F10: event conditioner | G10: no freshwater fallback
A11: Scenario loss | B11: DR × value × exposure | C11: conditional after release | D11: same-substation value, ownership and exposure required | E11: no full TIV or mixed 72 USD/kW | F11: one physical GSU | G11: not emitted here
A12: Annual/tail | B12: EAL / PML / VaR / TVaR | C12: withheld | D12: frequency, aggregation, and full coverage absent | E12: consumer-owned | F12: portfolio | G12: no result

Sheet Hazus_Source
A1: FEMA Hazus-MH 2.1 Table 7.9 transcription
A2: Source-native whole-substation ordinates; current Hazus 7.0 disables electric-power loss results
A4: Depth (ft) | B4: Source damage (%) | C4: Source DR | D4: Artifact DR | E4: Absolute delta | F4: Source ID | G4: Admission
A5: 0 | B5: 0 | C5: =B5/100 | D5: 0 | E5: =ABS(C5-D5) | F5: FW-S011 | G5: canonical partial screening only
A6: 1 | B6: 2 | C6: =B6/100 | D6: 0.02 | E6: =ABS(C6-D6) | F6: FW-S011 | G6: canonical partial screening only
A7: 2 | B7: 4 | C7: =B7/100 | D7: 0.04 | E7: =ABS(C7-D7) | F7: FW-S011 | G7: canonical partial screening only
A8: 3 | B8: 6 | C8: =B8/100 | D8: 0.06 | E8: =ABS(C8-D8) | F8: FW-S011 | G8: canonical partial screening only
A9: 4 | B9: 7 | C9: =B9/100 | D9: 0.07 | E9: =ABS(C9-D9) | F9: FW-S011 | G9: canonical partial screening only
A10: 5 | B10: 8 | C10: =B10/100 | D10: 0.08 | E10: =ABS(C10-D10) | F10: FW-S011 | G10: canonical partial screening only
A11: 6 | B11: 9 | C11: =B11/100 | D11: 0.09 | E11: =ABS(C11-D11) | F11: FW-S011 | G11: canonical partial screening only
A12: 7 | B12: 10 | C12: =B12/100 | D12: 0.1 | E12: =ABS(C12-D12) | F12: FW-S011 | G12: canonical partial screening only
A13: 8 | B13: 12 | C13: =B13/100 | D13: 0.12 | E13: =ABS(C13-D13) | F13: FW-S011 | G13: canonical partial screening only
A14: 9 | B14: 14 | C14: =B14/100 | D14: 0.14 | E14: =ABS(C14-D14) | F14: FW-S011 | G14: canonical partial screening only
A15: 10 | B15: 15 | C15: =B15/100 | D15: 0.15 | E15: =ABS(C15-D15) | F15: FW-S011 | G15: canonical partial screening only
A18: Source | B18: Version | C18: Locator | D18: What it supports | E18: What it does not support | F18: Current-status warning | G18: URL
A19: FEMA Hazus Flood Technical Manual | B19: 2.1 | C19: §7.2.4; Table 7.9, pp. 7-20–7-21 | D19: exact aggregate depth-percent table and narrative | E19: component calibration, duration, velocity, salinity, claims validation | F19: electric-power implementation described as deferred | G19: https://www.fema.gov/sites/default/files/2020-09/fema_hazus_flood-model_technical-manual_2.1.pdf
A20: FEMA Hazus Flood Technical Manual | B20: 7.0 | C20: Table 9-1; §9.4.1 footnote 21 | D20: authoritative current limitation | E20: no DR calibration | F20: mapping-only; visible electric damage functions disabled and produce no results | G20: https://www.fema.gov/sites/default/files/documents/fema_rsl_hazus-7-fltm_06272025_0.pdf
A21: Decision | B21: model v1.0 proposal | C21: governance package | D21: reviewable screening sensitivity | E21: canonical runtime or consumer cutover | F21: promotion gate blocked

Sheet Curve
A1: Piecewise-linear screening curve
A2: Exact linear interpolation between one-foot source knots; no clamping or extrapolation
A4: Test depth (ft) | B4: Lower knot | C4: Upper knot | D4: Formula DR | E4: Expected DR | F4: Status
A5: 0.5 | B5: 0 | C5: 1 | D5: ='Hazus_Source'!C5+(A5-B5)*(('Hazus_Source'!C6-'Hazus_Source'!C5)/(C5-B5)) | E5: 0.01 | F5: =IF(D5=E5,"PASS","FAIL")
A6: 1.5 | B6: 1 | C6: 2 | D6: ='Hazus_Source'!C6+(A6-B6)*(('Hazus_Source'!C7-'Hazus_Source'!C6)/(C6-B6)) | E6: 0.03 | F6: =IF(D6=E6,"PASS","FAIL")
A7: 2.5 | B7: 2 | C7: 3 | D7: ='Hazus_Source'!C7+(A7-B7)*(('Hazus_Source'!C8-'Hazus_Source'!C7)/(C7-B7)) | E7: 0.05 | F7: =IF(D7=E7,"PASS","FAIL")
A8: 3.5 | B8: 3 | C8: 4 | D8: ='Hazus_Source'!C8+(A8-B8)*(('Hazus_Source'!C9-'Hazus_Source'!C8)/(C8-B8)) | E8: 0.065 | F8: =IF(D8=E8,"PASS","FAIL")
A9: 4.5 | B9: 4 | C9: 5 | D9: ='Hazus_Source'!C9+(A9-B9)*(('Hazus_Source'!C10-'Hazus_Source'!C9)/(C9-B9)) | E9: 0.075 | F9: =IF(D9=E9,"PASS","FAIL")
A10: 5.5 | B10: 5 | C10: 6 | D10: ='Hazus_Source'!C10+(A10-B10)*(('Hazus_Source'!C11-'Hazus_Source'!C10)/(C10-B10)) | E10: 0.085 | F10: =IF(D10=E10,"PASS","FAIL")
A11: 6.5 | B11: 6 | C11: 7 | D11: ='Hazus_Source'!C11+(A11-B11)*(('Hazus_Source'!C12-'Hazus_Source'!C11)/(C11-B11)) | E11: 0.095 | F11: =IF(D11=E11,"PASS","FAIL")
A12: 7.5 | B12: 7 | C12: 8 | D12: ='Hazus_Source'!C12+(A12-B12)*(('Hazus_Source'!C13-'Hazus_Source'!C12)/(C12-B12)) | E12: 0.11 | F12: =IF(D12=E12,"PASS","FAIL")
A13: 8.5 | B13: 8 | C13: 9 | D13: ='Hazus_Source'!C13+(A13-B13)*(('Hazus_Source'!C14-'Hazus_Source'!C13)/(C13-B13)) | E13: 0.13 | F13: =IF(D13=E13,"PASS","FAIL")
A14: 9.5 | B14: 9 | C14: 10 | D14: ='Hazus_Source'!C14+(A14-B14)*(('Hazus_Source'!C15-'Hazus_Source'!C14)/(C14-B14)) | E14: 0.145 | F14: =IF(D14=E14,"PASS","FAIL")
A17: Rule | B17: Value | C17: Guardrail
A18: curve_form | B18: piecewise_linear | C18: schema v3 draft extension
A19: interpolation | B19: linear_between_source_knots | C19: only between source knots
A20: valid range | B20: 0 through 10 ft inclusive | C20: negative rejects; >10 withholds
A21: extrapolation | B21: withhold outside 0 through 10 ft; no endpoint clamp | C21: no endpoint clamp
A22: output | B22: conditional scalar failure-unit DR | C22: not scenario loss

Sheet Axis_Bridge
A1: Datum-safe WSE-to-grade bridge
A2: Direct source-native depth is preferred; an exact same-datum elevation difference may be converted to feet
A4: WSE (m) | B4: Grade (m) | C4: WSE datum | D4: Grade datum | E4: Derived depth (ft) | F4: Datum status | G4: Runtime disposition
A5: 100.3048 | B5: 100 | C5: NAVD88 | D5: NAVD88 | E5: =(A5-B5)*3.280839895013123 | F5: =IF(C5=D5,"PASS","WITHHOLD") | G5: =IF(F5<>"PASS","WITHHOLD_DATUM",IF(E5<0,"REJECT_NEGATIVE",IF(E5>10,"WITHHOLD_RANGE","ELIGIBLE")))
A6: 101 | B6: 100 | C6: NAVD88 | D6: NAVD88 | E6: =(A6-B6)*3.280839895013123 | F6: =IF(C6=D6,"PASS","WITHHOLD") | G6: =IF(F6<>"PASS","WITHHOLD_DATUM",IF(E6<0,"REJECT_NEGATIVE",IF(E6>10,"WITHHOLD_RANGE","ELIGIBLE")))
A7: 101 | B7: 100 | C7: NAVD88 | D7: NGVD29 | E7: =(A7-B7)*3.280839895013123 | F7: =IF(C7=D7,"PASS","WITHHOLD") | G7: =IF(F7<>"PASS","WITHHOLD_DATUM",IF(E7<0,"REJECT_NEGATIVE",IF(E7>10,"WITHHOLD_RANGE","ELIGIBLE")))
A8: 99.9 | B8: 100 | C8: NAVD88 | D8: NAVD88 | E8: =(A8-B8)*3.280839895013123 | F8: =IF(C8=D8,"PASS","WITHHOLD") | G8: =IF(F8<>"PASS","WITHHOLD_DATUM",IF(E8<0,"REJECT_NEGATIVE",IF(E8>10,"WITHHOLD_RANGE","ELIGIBLE")))
A9: 103.2 | B9: 100 | C9: LOCAL | D9: LOCAL | E9: =(A9-B9)*3.280839895013123 | F9: =IF(C9=D9,"PASS","WITHHOLD") | G9: =IF(F9<>"PASS","WITHHOLD_DATUM",IF(E9<0,"REJECT_NEGATIVE",IF(E9>10,"WITHHOLD_RANGE","ELIGIBLE")))
A12: Input mode | B12: Required fields | C12: Mutual exclusion | D12: Fail-closed rule
A13: direct_depth_ft | B13: flood_depth_above_substation_grade_ft | C13: cannot accompany WSE fields | D13: negative rejects; >10 withholds
A14: same_datum_wse_grade_m | B14: WSE, grade, both datum IDs | C14: cannot accompany direct depth | D14: missing/mismatched datum rejects

Sheet Failure_Units
A1: Failure-unit coverage
A2: Only the source-native assembly has a numeric screening record; every other unit remains withheld, not zero
A4: Failure unit | B4: Subsystem | C4: Component / boundary | D4: Treatment | E4: Y axis | F4: Denominator | G4: Exposure grain | H4: Withhold reasons
A5: FW_HAZUS_GSU_SUBSTATION_ASSEMBLY | B5: FACILITY GSU SUBSTATION SOURCE NATIVE | C5: HAZUS SUBSTATION CONTROL ROOM CABLING AND INCIDENTAL TRANSFORMER SWITCHGEAR ASSEMBLY | D5: primary nonzero | E5: failure_unit_damage_ratio | F5: full direct replacement value of the same facility-level substation assembly | G5: one real facility-level GSU/substation point or polygon
A6: FW_GSU_SWITCHGEAR | B6: FACILITY GSU SUBSTATION | C6: SWITCHGEAR | D6: withheld | E6: failure_unit_damage_ratio | F6: same-unit switchgear replacement value | G6: future exact unit | H6: NO_RUNTIME_CURVE_FOR_PATHWAY_UNIT; COMPONENT_LEVEL_ECONOMIC_RESPONSE_NOT_CALIBRATED
A7: FW_GSU_TRANSFORMER_MAIN | B7: FACILITY GSU SUBSTATION | C7: PLANT GSU MAIN TRANSFORMER | D7: withheld | E7: failure_unit_damage_ratio | F7: same-unit main-transformer replacement value | G7: future exact unit | H7: NO_RUNTIME_CURVE_FOR_PATHWAY_UNIT; TRANSFORMER_MAIN_AUXILIARY_STATE_MODEL_REQUIRED
A8: FW_GSU_TRANSFORMER_AUX_CONTROLS | B8: FACILITY GSU SUBSTATION | C8: TRANSFORMER AUXILIARIES AND CONTROLS | D8: withheld | E8: failure_unit_damage_ratio | F8: same-unit transformer auxiliary/control replacement value | G8: future exact unit | H8: NO_RUNTIME_CURVE_FOR_PATHWAY_UNIT; DEPENDENCY_SAFE_VALUE_SPLIT_REQUIRED
A9: FW_GSU_PROTECTION_SCADA | B9: FACILITY GSU SUBSTATION | C9: PROTECTION RELAY CONTROL SCADA COMMUNICATIONS | D9: withheld | E9: failure_unit_damage_ratio | F9: same-unit protection relay control and communications replacement value | G9: future exact unit | H9: NO_RUNTIME_CURVE_FOR_PATHWAY_UNIT; PROTECTION_CONTROL_ECONOMIC_RESPONSE_NOT_CALIBRATED
A10: FW_GSU_STATION_SERVICE_DC | B10: FACILITY GSU SUBSTATION | C10: STATION SERVICE AND DC POWER | D10: withheld | E10: failure_unit_damage_ratio | F10: same-unit station service and DC replacement value | G10: future exact unit | H10: NO_RUNTIME_CURVE_FOR_PATHWAY_UNIT; STATION_SERVICE_DC_DECOMPOSITION_REQUIRED
A11: FW_GSU_CABLE_TERMINATIONS | B11: FACILITY GSU SUBSTATION | C11: CABLE TERMINATIONS PULL BOXES AND WATER PATHS | D11: withheld | E11: failure_unit_damage_ratio | F11: same-unit termination or pathway-segment replacement value | G11: future exact unit | H11: NO_RUNTIME_CURVE_FOR_PATHWAY_UNIT; CABLE_BODY_TERMINATION_PATHWAY_SPLIT_REQUIRED
A12: FW_TURBINE_BASE_ELECTRICAL | B12: REPEATED TURBINE ELECTRICAL | C12: BASE CABINET CONVERTER SWITCHGEAR OR CONTROL | D12: withheld | E12: failure_unit_damage_ratio | F12: same-unit turbine-base electrical replacement value | G12: future exact unit | H12: NO_RUNTIME_CURVE_FOR_PATHWAY_UNIT; WIND_SPECIFIC_EQUIPMENT_DECOMPOSITION_REQUIRED
A13: FW_PADMOUNT_STEPUP_TRANSFORMER | B13: REPEATED TURBINE ELECTRICAL | C13: PAD OR TURBINE STEPUP TRANSFORMER | D13: withheld | E13: failure_unit_damage_ratio | F13: same-unit pad or turbine step-up transformer replacement value | G13: future exact unit | H13: NO_RUNTIME_CURVE_FOR_PATHWAY_UNIT; PAD_TRANSFORMER_CONSTRUCTION_AND_VALUE_REQUIRED
A14: FW_COLLECTION_CABLE_TERMINATIONS | B14: PLANT COLLECTION | C14: MV CABLE JOINT TERMINATION PULL BOX OR CONDUIT PATH | D14: withheld | E14: failure_unit_damage_ratio | F14: same point or line-segment replacement value | G14: future exact unit | H14: NO_RUNTIME_CURVE_FOR_PATHWAY_UNIT; LINE_NETWORK_EXPOSURE_AND_VALUE_REQUIRED
A15: FW_TURBINE_FOUNDATION | B15: FOUNDATION | C15: TURBINE FOUNDATION AND SUPPORTING SOIL | D15: withheld | E15: failure_unit_damage_ratio | F15: same-unit turbine foundation replacement value | G15: future exact unit | H15: NO_RUNTIME_CURVE_FOR_PATHWAY_UNIT; SEPARATE_FLOOD_SCOUR_EROSION_PATHWAY_REQUIRED
A16: FW_CIVIL_ACCESS_DRAINAGE | B16: PLANT CIVIL | C16: ROADS PADS DRAINAGE BUILDINGS AND FENCES MIXED | D16: withheld | E16: failure_unit_damage_ratio | F16: split same-unit civil replacement value | G16: future exact unit | H16: NO_RUNTIME_CURVE_FOR_PATHWAY_UNIT; MIXED_CIVIL_BUCKET_REQUIRES_SPLIT
A17: FW_ELEVATED_TURBINE_EQUIPMENT | B17: REPEATED TURBINE | C17: ELEVATED ROTOR NACELLE AND TOWER EQUIPMENT | D17: withheld | E17: failure_unit_damage_ratio | F17: same-unit elevated turbine-equipment replacement value | G17: future exact unit | H17: NO_RUNTIME_CURVE_FOR_PATHWAY_UNIT; GEOMETRY_SCREENED_NOT_UNIVERSAL_ZERO
... A19: SUPPORT_TRANSPORT_LOGISTICS | B19: SUPPORT | C19: WIND TURBINE TRANSPORT AND LOGISTICS | D19: withheld | E19: not_applicable_support_cost | F19: post-damage replacement logistics scope | G19: future exact unit | H19: SUPPORT_COST_ALLOCATE_ONCE_AFTER_DISPOSITION; NO_INDEPENDENT_FRAGILITY

Sheet Value_Crosswalk
A1: Value and denominator crosswalk
A2: Reference value anatomy stays visible; no full-project TIV, mixed 72 USD/kW, or per-turbine GSU repetition
A4: value_source_id | B4: source_location | C4: row_or_bucket_id | D4: row_or_bucket_label | E4: value | F4: unit | G4: financial_class | H4: failure_unit_id | I4: applicable_pathway_ids | J4: role_in_loss | K4: include_in_direct_denominator | L4: allocation_rule | M4: double_count_guardrail | N4: status | O4: notes
A5: SITE_SOV_BOM_APPRAISAL | B5: site-controlled SOV, BOM, replacement appraisal, one-line, ownership agreement, and insured schedule | C5: FW_VALUE_HAZUS_GSU_SUBSTATION_ASSEMBLY | D5: Complete same-facility GSU/substation assembly | F5: site_USD_required | G5: direct_hardware | H5: FW_HAZUS_GSU_SUBSTATION_ASSEMBLY | I5: flood_inundation_contact | J5: direct_vulnerable_value_after_promotion | K5: true | L5: Bind DR to the full non-overlapping direct replacement value of one actual facility-level GSU/substation; require value basis/date/currency, quantity one, exposure fraction, owner, project-owned status, and insured inclusion for insured views. | M5: Mutually exclusive with all six FW_GSU component rows; do not use full project TIV, the 72 USD/kW mixed row, the legacy 9% share, or repeat one facility substation by turbine count. | N5: required_external_withheld_before_promotion | O5: Evaluator emits DR; scenario value binding is consumer-side and requires explicit same-substation value and exposure.
A6: NREL_CWER_2024 | B6: docs/method/value_basis/solar_wind_value_breakdown.xlsx::Wind_Map!12 | C6: WIND_VALUE_012_ELECTRICAL | D6: Electrical infrastructure | E6: 72 | F6: 2023_USD_per_kW | G6: mixed_direct_hardware | H6: FW_ELECTRICAL_ROLLUP_UNSPLIT | I6: flood_inundation_contact | J6: split_required | K6: false | L6: Split among turbine-base, pad, collection, and substation components using a site/OEM schedule before any component loss. | M6: Never use as the Hazus assembly denominator; do not add a legacy 9% substation share or repeat one GSU per turbine. | N6: withheld_split_required | O6: Reference rollup only.
A7: NREL_CWER_2024 | B7: Wind_Map!12 | C7: FW_VALUE_GSU_SWITCHGEAR | D7: Substation switchgear | F7: site_USD_required | G7: direct_hardware | H7: FW_GSU_SWITCHGEAR | I7: flood_inundation_contact | J7: direct_vulnerable_value | K7: false | L7: Site component value and ownership required for a future component record. | M7: When FW_HAZUS_GSU_SUBSTATION_ASSEMBLY is selected, this component value and response must be excluded; never apply DR to the full 72 USD/kW row or project TIV. | N7: withheld_value_curve_and_ownership | O7: No public split and no component runtime curve.
A8: NREL_CWER_2024 | B8: Wind_Map!12 | C8: FW_VALUE_GSU_TRANSFORMER_MAIN | D8: Plant GSU main transformer | F8: site_USD_required | G8: direct_hardware | H8: FW_GSU_TRANSFORMER_MAIN | I8: flood_inundation_contact | J8: direct_vulnerable_value | K8: false | L8: Site component value and ownership required for a future component record. | M8: When FW_HAZUS_GSU_SUBSTATION_ASSEMBLY is selected, exclude this row; do not use control exposure against full transformer value without a dependency-safe state. | N8: withheld_value_curve_and_ownership | O8: No public split and no component runtime curve.
A9: NREL_CWER_2024 | B9: Wind_Map!12 | C9: FW_VALUE_GSU_TRANSFORMER_AUX | D9: GSU auxiliaries and controls | F9: site_USD_required | G9: direct_hardware | H9: FW_GSU_TRANSFORMER_AUX_CONTROLS | I9: flood_inundation_contact | J9: direct_vulnerable_value | K9: false | L9: Separate SOV/BOM or dependency-safe assembly required for a future component record. | M9: When FW_HAZUS_GSU_SUBSTATION_ASSEMBLY is selected, exclude this row; never duplicate value inside main transformer and auxiliaries. | N9: withheld_value_curve_and_ownership | O9: No public split and no component runtime curve.
A10: NREL_CWER_2024 | B10: Wind_Map!12 | C10: FW_VALUE_GSU_PROTECTION | D10: Protection SCADA and control | F10: site_USD_required | G10: direct_hardware | H10: FW_GSU_PROTECTION_SCADA | I10: flood_inundation_contact | J10: direct_vulnerable_value | K10: false | L10: Separate physical equipment value from outage consequence for a future component record. | M10: When FW_HAZUS_GSU_SUBSTATION_ASSEMBLY is selected, exclude this row; never convert MW outage to value or add plant BI. | N10: withheld_value_curve_and_ownership | O10: No public split and no component runtime curve.
A11: NREL_CWER_2024 | B11: Wind_Map!12 | C11: FW_VALUE_GSU_STATION_DC | D11: Station service and DC power | F11: site_USD_required | G11: direct_hardware | H11: FW_GSU_STATION_SERVICE_DC | I11: flood_inundation_contact | J11: direct_vulnerable_value | K11: false | L11: Site equipment schedule required for a future component record. | M11: When FW_HAZUS_GSU_SUBSTATION_ASSEMBLY is selected, exclude this row; never include it twice through protection/control value. | N11: withheld_value_curve_and_ownership | O11: No public split and no component runtime curve.
A12: NREL_CWER_2024 | B12: Wind_Map!12 | C12: FW_VALUE_GSU_TERMINATIONS | D12: GSU cable terminations and pathways | F12: site_USD_required | G12: direct_hardware | H12: FW_GSU_CABLE_TERMINATIONS | I12: flood_inundation_contact | J12: direct_vulnerable_value | K12: false | L12: Separate cable body, joints, terminations, pull boxes, and conduits for a future component record. | M12: When FW_HAZUS_GSU_SUBSTATION_ASSEMBLY is selected, exclude this row; never apply a full cable-rollup DR to pathway damage. | N12: withheld_value_curve_and_ownership | O12: No public split and no component runtime curve.
A13: NREL_CWER_2024 | B13: Wind_Map!12 | C13: FW_VALUE_TURBINE_BASE | D13: Turbine-base power electronics and switchgear | F13: site_USD_required | G13: direct_hardware | H13: FW_TURBINE_BASE_ELECTRICAL | I13: flood_inundation_contact | J13: direct_vulnerable_value | K13: false | L13: Split per turbine/cluster and use local equipment value. | M13: Do not use solar inverter value, the Hazus facility-substation DR, or the full electrical rollup. | N13: withheld_split_and_curve_required | O13: Wind-specific inventory.
A14: NREL_CWER_2024 | B14: Wind_Map!12 | C14: FW_VALUE_PAD_TRANSFORMER | D14: Pad or turbine step-up transformer | F14: site_USD_required | G14: direct_hardware | H14: FW_PADMOUNT_STEPUP_TRANSFORMER | I14: flood_inundation_contact | J14: direct_vulnerable_value | K14: false | L14: Split by installed units and ownership. | M14: Do not include inside turbine equipment and external electrical twice or use the Hazus facility-substation DR. | N14: withheld_split_and_curve_required | O14: Wind-specific inventory.
A15: NREL_CWER_2024 | B15: Wind_Map!12 | C15: FW_VALUE_COLLECTION_TERMINATIONS | D15: Wind MV collection cable terminations | F15: site_USD_required | G15: direct_hardware | H15: FW_COLLECTION_CABLE_TERMINATIONS | I15: flood_inundation_contact | J15: direct_vulnerable_value | K15: false | L15: Segment/termination schedule and line-network exposure required. | M15: Do not allocate by turbine count alone or use the Hazus facility-substation DR. | N15: withheld_split_and_curve_required | O15: Wind-specific inventory.
A16: NREL_CWER_2024 | B16: Wind_Map!10 | C16: WIND_VALUE_010_FOUNDATION | D16: Foundation | E16: 120 | F16: 2023_USD_per_kW | G16: direct_hardware | H16: FW_TURBINE_FOUNDATION | I16: flood_scour_erosion | J16: withheld_separate_pathway | K16: false | L16: Site foundation type/value and hydraulic/geotechnical response required. | M16: Do not use the Hazus assembly curve, legacy depth logistic, or treat missing response as zero. | N16: withheld | O16: Reference value only.
A17: NREL_CWER_2024 | B17: Wind_Map!11 | C17: WIND_VALUE_011_CIVIL | D17: Site access staging and facilities | E17: 47 | F17: 2023_USD_per_kW | G17: mixed_civil | H17: FW_CIVIL_ACCESS_DRAINAGE | I17: flood_scour_erosion | J17: split_required | K17: false | L17: Split roads, pads, drainage, buildings, and fences before exposure/value. | M17: Do not apply one civil depth curve or the Hazus assembly curve to the mixed row. | N17: withheld | O17: Reference value only.
A18: NREL_CWER_2024 | B18: Wind_Map!2:9 | C18: WT_ELEVATED_EQUIPMENT_TOTAL | D18: Elevated turbine equipment | E18: 1090 | F18: 2023_USD_per_kW | G18: direct_hardware | H18: FW_ELEVATED_TURBINE_EQUIPMENT | I18: flood_inundation_contact | J18: reconciliation_geometry_screen | K18: false | L18: Include only if water reaches a documented vulnerable path/component; otherwise geometry-screened. | M18: Do not declare universal immunity, use the share as a DR cap, or apply the Hazus facility-substation curve. | N18: withheld_geometry_dependent | O18: Rotor nacelle tower/equipment reference rollup.
A19: NREL_CWER_2024 | B19: Wind_Map!13 | C19: WIND_VALUE_013_FIELDWORK | D19: Assembly and installation | E19: 100 | F19: 2023_USD_per_kW | G19: support_logistics | H19: SUPPORT_FIELDWORK | I19: all_shared | J19: support_once | K19: false | L19: Allocate once after qualified repair scope and only under a reviewed consumer value policy. | M19: No independent fragility, automatic proportional add-on, or duplication inside assembly replacement value. | N19: mapped_support_rule_open | O19: Reference only.
A20: NREL_CWER_2024 | B20: Wind_Map!14 | C20: WIND_VALUE_014_TRANSPORT | D20: Wind turbine transport | E20: 194 | F20: 2023_USD_per_kW | G20: support_logistics | H20: SUPPORT_TRANSPORT_LOGISTICS | I20: all_shared | J20: support_once | K20: false | L20: Allocate once when replacement and logistics require it and only under a reviewed consumer value policy. | M20: Do not include in the intrinsic DR denominator, add it again, or assume wind-turbine transport applies to substation repair. | N20: mapped_support_rule_open | O20: Reference only.
A21: SUMMARY | B21: Wind_Map!2:14 | C21: PHYSICAL_REFERENCE_TOTAL | D21: Physical reference basis | E21: 1623 | F21: 2023_USD_per_kW | G21: reconciliation | H21: REFERENCE_DENOMINATOR_ONLY | I21: all_shared | J21: reference | K21: false | L21: 1090 equipment + 120 foundation + 47 civil + 72 electrical + 294 support. | M21: No pooled physical-base DR and no Hazus assembly denominator. | N21: reconciled | O21: Reference reporting denominator only.
A22: SUMMARY | B22: Wind_Map!15:19 | C22: EXCLUDED_TOTAL | D22: Excluded soft sunk nonphysical | E22: 345 | F22: 2023_USD_per_kW | G22: reconciliation | H22: OUTSIDE_PHYSICAL_CELL | I22: all_shared | J22: excluded | K22: false | L22: Exclude from direct physical destruction by default. | M22: Do not reintroduce through damage or support scaling. | N22: reconciled | O22: Installed minus physical.
A23: SUMMARY | B23: Wind_Map!2:19 | C23: INSTALLED_REFERENCE_TOTAL | D23: Installed reference basis | E23: 1968 | F23: 2023_USD_per_kW | G23: reconciliation | H23: REFERENCE_REPORTING_DENOMINATOR | I23: all_shared | J23: reference | K23: false | L23: Reference reporting denominator only. | M23: No implicit full-TIV curve, Hazus assembly denominator, or scenario loss. | N23: reconciled | O23: Physical 1623 plus excluded 345.

Sheet Old_vs_New
A1: Old versus new
A2: The change is partial numerical coverage, not canonical admission or a whole-wind-farm model
A4: comparison_id | B4: request_case | C4: flood_depth_above_substation_grade_ft | D4: substation_hazus_class | E4: water_quality_class | F4: delivered_depth_basis | G4: source_assumption_set_id | H4: model_v0_1_runtime_assembly_dr | I4: model_v1_runtime_status | J4: model_v1_runtime_assembly_dr | K4: legacy_hazard_substation_bucket_curve_dr | L4: legacy_hazard_full_tiv_contribution_at_9pct | M4: axis_and_denominator_comparability | N4: comparison_disposition
A5: FW-CMP-000 | B5: source_knot_0_ft | C5: 0 | D5: ESSL | E5: freshwater_non_contaminated | F5: unprotected_or_internal_post_bypass_depth | G5: FEMA_HAZUS_MH_2_1_TABLE_7_9_UNPROTECTED_SUBSTATION | I5: conditional | J5: 0.000000000000 | K5: 0.000000000000 | L5: 0.000000000000 | M5: Depth is illustratively alignable in feet, but v1 is a whole-substation source atom and the legacy value is a fixed project-TIV bucket. | N5: v0.1 null is the behavioral baseline; exact v1 knot is a KAT; legacy output is audit-only.
A6: FW-CMP-001 | B6: source_knot_1_ft | C6: 1 | D6: ESSL | E6: freshwater_non_contaminated | F6: unprotected_or_internal_post_bypass_depth | G6: FEMA_HAZUS_MH_2_1_TABLE_7_9_UNPROTECTED_SUBSTATION | I6: conditional | J6: 0.020000000000 | K6: 0.189736630470 | L6: 0.017076296742 | M6: Same illustrative depth unit; response grain, formula, and denominator differ. | N6: Do not calibrate v1 to the legacy curve or compare numerical magnitude as regression equality.
A7: FW-CMP-002 | B7: source_knot_2_ft | C7: 2 | D7: ESSL | E7: freshwater_non_contaminated | F7: unprotected_or_internal_post_bypass_depth | G7: FEMA_HAZUS_MH_2_1_TABLE_7_9_UNPROTECTED_SUBSTATION | I7: conditional | J7: 0.040000000000 | K7: 0.716606366701 | L7: 0.064494573003 | M7: Same illustrative depth unit; response grain, formula, and denominator differ. | N7: Exact v1 source knot; legacy output is audit-only.
A8: FW-CMP-003 | B8: source_knot_3_ft | C8: 3 | D8: ESSM | E8: freshwater_non_contaminated | F8: unprotected_or_internal_post_bypass_depth | G8: FEMA_HAZUS_MH_2_1_TABLE_7_9_UNPROTECTED_SUBSTATION | I8: conditional | J8: 0.060000000000 | K8: 0.906342997171 | L8: 0.081570869745 | M8: Same illustrative depth unit; response grain, formula, and denominator differ. | N8: ESSM equals the other Hazus classes only within Table 7.9; legacy output is not a class-specific comparator.
A9: FW-CMP-004 | B9: source_knot_4_ft | C9: 4 | D9: ESSM | E9: freshwater_non_contaminated | F9: unprotected_or_internal_post_bypass_depth | G9: FEMA_HAZUS_MH_2_1_TABLE_7_9_UNPROTECTED_SUBSTATION | I9: conditional | J9: 0.070000000000 | K9: 0.926341100655 | L9: 0.083370699059 | M9: Same illustrative depth unit; v1 direct physical substation DR is not the legacy functionality threshold or full-TIV bucket. | N9: Four-foot source functionality context does not alter the v1 direct-cost curve.
A10: FW-CMP-005 | B10: source_knot_5_ft | C10: 5 | D10: ESSM | E10: freshwater_non_contaminated | F10: unprotected_or_internal_post_bypass_depth | G10: FEMA_HAZUS_MH_2_1_TABLE_7_9_UNPROTECTED_SUBSTATION | I10: conditional | J10: 0.080000000000 | K10: 0.928020984177 | L10: 0.083521888576 | M10: Same illustrative depth unit; response grain, formula, and denominator differ. | N10: Exact v1 source knot; legacy saturation behavior is not a target.
A11: FW-CMP-006 | B11: source_knot_6_ft | C11: 6 | D11: ESSH | E11: freshwater_non_contaminated | F11: unprotected_or_internal_post_bypass_depth | G11: FEMA_HAZUS_MH_2_1_TABLE_7_9_UNPROTECTED_SUBSTATION | I11: conditional | J11: 0.090000000000 | K11: 0.928159141813 | L11: 0.083534322763 | M11: Same illustrative depth unit; response grain, formula, and denominator differ. | N11: Exact v1 source knot; legacy output is audit-only.
A12: FW-CMP-007 | B12: source_knot_7_ft | C12: 7 | D12: ESSH | E12: freshwater_non_contaminated | F12: unprotected_or_internal_post_bypass_depth | G12: FEMA_HAZUS_MH_2_1_TABLE_7_9_UNPROTECTED_SUBSTATION | I12: conditional | J12: 0.100000000000 | K12: 0.928170484268 | L12: 0.083535343584 | M12: Same illustrative depth unit; response grain, formula, and denominator differ. | N12: Exact v1 source knot; legacy output is audit-only.
A13: FW-CMP-008 | B13: source_knot_8_ft | C13: 8 | D13: ESSL | E13: freshwater_non_contaminated | F13: unprotected_or_internal_post_bypass_depth | G13: FEMA_HAZUS_MH_2_1_TABLE_7_9_UNPROTECTED_SUBSTATION | I13: conditional | J13: 0.120000000000 | K13: 0.928171415325 | L13: 0.083535427379 | M13: Same illustrative depth unit; response grain, formula, and denominator differ. | N13: Exact v1 source knot; legacy output is audit-only.
A14: FW-CMP-009 | B14: source_knot_9_ft | C14: 9 | D14: ESSM | E14: freshwater_non_contaminated | F14: unprotected_or_internal_post_bypass_depth | G14: FEMA_HAZUS_MH_2_1_TABLE_7_9_UNPROTECTED_SUBSTATION | I14: conditional | J14: 0.140000000000 | K14: 0.928171491751 | L14: 0.083535434258 | M14: Same illustrative depth unit; response grain, formula, and denominator differ. | N14: Exact v1 source knot; legacy output is audit-only.
A15: FW-CMP-010 | B15: source_knot_10_ft | C15: 10 | D15: ESSH | E15: freshwater_non_contaminated | F15: unprotected_or_internal_post_bypass_depth | G15: FEMA_HAZUS_MH_2_1_TABLE_7_9_UNPROTECTED_SUBSTATION | I15: conditional | J15: 0.150000000000 | K15: 0.928171498024 | L15: 0.083535434822 | M15: Same illustrative depth unit; response grain, formula, and denominator differ. | N15: Exact upper v1 boundary; do not extend it with the legacy tail.
A16: FW-CMP-011 | B16: above_source_range | C16: 10.1 | D16: ESSL | E16: freshwater_non_contaminated | F16: unprotected_or_internal_post_bypass_depth | G16: FEMA_HAZUS_MH_2_1_TABLE_7_9_UNPROTECTED_SUBSTATION | I16: withheld_ABOVE_SOURCE_VALID_RANGE | M16: V1 has no source support above 10 ft; legacy formula/denominator remain incomparable. | N16: Withhold; do not clamp, extrapolate, or fall back to the legacy curve.
A17: FW-CMP-012 | B17: negative_direct_depth | C17: -0.1 | D17: ESSL | E17: freshwater_non_contaminated | F17: unprotected_or_internal_post_bypass_depth | G17: FEMA_HAZUS_MH_2_1_TABLE_7_9_UNPROTECTED_SUBSTATION | I17: reject_AXIS_OUTSIDE_VALID_RANGE | M17: Negative delivered depth is invalid rather than a dry-state proxy. | N17: Reject; do not floor to zero.
A18: FW-CMP-013 | B18: unsupported_recognized_water | C18: 5 | D18: ESSL | E18: saltwater | F18: unprotected_or_internal_post_bypass_depth | G18: FEMA_HAZUS_MH_2_1_TABLE_7_9_UNPROTECTED_SUBSTATION | I18: withheld_WATER_QUALITY_OUTSIDE_SCREENING_DOMAIN | K18: 0.928020984177 | L18: 0.083521888576 | M18: The legacy implementation lacks the governed water-quality gate and has a different denominator. | N18: Withhold; never use the legacy numeric as fallback.
A19: FW-CMP-014 | B19: unknown_water_enum | C19: 5 | D19: ESSL | E19: seawater | F19: unprotected_or_internal_post_bypass_depth | G19: FEMA_HAZUS_MH_2_1_TABLE_7_9_UNPROTECTED_SUBSTATION | I19: reject_WATER_QUALITY_CLASS_UNKNOWN | K19: 0.928020984177 | L19: 0.083521888576 | M19: The request enum is invalid and the old curve did not enforce this contract. | N19: Reject and correct metadata.
A20: FW-CMP-015 | B20: unsupported_depth_basis | C20: 5 | D20: ESSL | E20: freshwater_non_contaminated | F20: external_grade_depth_before_protection | G20: FEMA_HAZUS_MH_2_1_TABLE_7_9_UNPROTECTED_SUBSTATION | I20: reject_DELIVERED_DEPTH_BASIS_UNSUPPORTED | K20: 0.928020984177 | L20: 0.083521888576 | M20: External pre-protection depth is not equivalent to the delivered internal basis; legacy behavior is incomparable. | N20: Reject; resolve protection once upstream.
A21: FW-CMP-016 | B21: unsupported_source_class | C21: 5 | D21: UNKNOWN | E21: freshwater_non_contaminated | F21: unprotected_or_internal_post_bypass_depth | G21: FEMA_HAZUS_MH_2_1_TABLE_7_9_UNPROTECTED_SUBSTATION | I21: reject_SUBSTATION_HAZUS_CLASS_UNSUPPORTED | K21: 0.928020984177 | L21: 0.083521888576 | M21: The source requires an exact class while the legacy curve used no such selector. | N21: Reject; do not default a favorable class.
A22: FW-CMP-017 | B22: unsupported_assumption_set | C22: 5 | D22: ESSL | E22: freshwater_non_contaminated | F22: unprotected_or_internal_post_bypass_depth | G22: UNACKNOWLEDGED | I22: reject_SOURCE_ASSUMPTION_SET_UNSUPPORTED | K22: 0.928020984177 | L22: 0.083521888576 | M22: The v1 source assumptions are explicit; the legacy curve did not preserve them. | N22: Reject; do not silently acknowledge the legacy FEMA atom.
A23: FW-CMP-018 | B23: ambiguous_axis_payload | C23: 5 | D23: ESSL | E23: freshwater_non_contaminated | F23: unprotected_or_internal_post_bypass_depth | G23: FEMA_HAZUS_MH_2_1_TABLE_7_9_UNPROTECTED_SUBSTATION | I23: reject_AXIS_PAYLOAD_AMBIGUOUS | M23: This case additionally supplies WSE/grade bridge fields, so two payload modes conflict. | N23: Reject; retain exactly one axis payload.
A24: FW-CMP-019 | B24: component_failure_unit | C24: 5 | D24: ESSL | E24: freshwater_non_contaminated | F24: unprotected_or_internal_post_bypass_depth | G24: FEMA_HAZUS_MH_2_1_TABLE_7_9_UNPROTECTED_SUBSTATION | I24: withheld_NO_RUNTIME_CURVE_FOR_PATHWAY_UNIT | K24: 0.928020984177 | L24: 0.083521888576 | M24: The v1 curve is a mutually exclusive whole-substation atom; the legacy bucket is not a component curve. | N24: Withhold component DR; do not decompose or copy the assembly response.

Sheet KATs
A1: Known-answer and fail-closed test inventory
A2: The Python validator executes these fixtures through the reference evaluator
A4: Test ID | B4: Class | C4: Input | D4: Expected status | E4: Expected DR | F4: Curve / reason | G4: Execution | H4: Row complete?
A5: FW_HAZUS_KNOT_00FT | B5: formula | C5: {"pathway_id":"flood_inundation_contact","failure_unit_id":"FW_HAZUS_GSU_SUBSTATION_ASSEMBLY","substation_hazus_class":"ESSL","source_assumption_set_id":"FEMA_HAZUS_MH_2_1_TABLE_7_9_UNPROTECTED_SUBSTATION","water_quality_class":"freshwater_non_contaminated","delivered_depth_basis":"unprotected_or_internal_post_bypass_depth","flood_depth_above_substation_grade_ft":0} | D5: conditional | E5: 0 | F5: FW_HAZUS_2_1_SUBSTATION_SCREENING_PWL | G5: executed externally | H5: =IF(AND(A5<>"",D5<>"",F5<>""),"PASS","FAIL")
A6: FW_HAZUS_KNOT_01FT | B6: formula | C6: {"pathway_id":"flood_inundation_contact","failure_unit_id":"FW_HAZUS_GSU_SUBSTATION_ASSEMBLY","substation_hazus_class":"ESSM","source_assumption_set_id":"FEMA_HAZUS_MH_2_1_TABLE_7_9_UNPROTECTED_SUBSTATION","water_quality_class":"freshwater_non_contaminated","delivered_depth_basis":"unprotected_or_internal_post_bypass_depth","flood_depth_above_substation_grade_ft":1} | D6: conditional | E6: 0.02 | F6: FW_HAZUS_2_1_SUBSTATION_SCREENING_PWL | G6: executed externally | H6: =IF(AND(A6<>"",D6<>"",F6<>""),"PASS","FAIL")
A7: FW_HAZUS_KNOT_02FT | B7: formula | C7: {"pathway_id":"flood_inundation_contact","failure_unit_id":"FW_HAZUS_GSU_SUBSTATION_ASSEMBLY","substation_hazus_class":"ESSH","source_assumption_set_id":"FEMA_HAZUS_MH_2_1_TABLE_7_9_UNPROTECTED_SUBSTATION","water_quality_class":"freshwater_non_contaminated","delivered_depth_basis":"unprotected_or_internal_post_bypass_depth","flood_depth_above_substation_grade_ft":2} | D7: conditional | E7: 0.04 | F7: FW_HAZUS_2_1_SUBSTATION_SCREENING_PWL | G7: executed externally | H7: =IF(AND(A7<>"",D7<>"",F7<>""),"PASS","FAIL")
A8: FW_HAZUS_KNOT_03FT | B8: formula | C8: {"pathway_id":"flood_inundation_contact","failure_unit_id":"FW_HAZUS_GSU_SUBSTATION_ASSEMBLY","substation_hazus_class":"ESSL","source_assumption_set_id":"FEMA_HAZUS_MH_2_1_TABLE_7_9_UNPROTECTED_SUBSTATION","water_quality_class":"freshwater_non_contaminated","delivered_depth_basis":"unprotected_or_internal_post_bypass_depth","flood_depth_above_substation_grade_ft":3} | D8: conditional | E8: 0.06 | F8: FW_HAZUS_2_1_SUBSTATION_SCREENING_PWL | G8: executed externally | H8: =IF(AND(A8<>"",D8<>"",F8<>""),"PASS","FAIL")
A9: FW_HAZUS_KNOT_04FT | B9: formula | C9: {"pathway_id":"flood_inundation_contact","failure_unit_id":"FW_HAZUS_GSU_SUBSTATION_ASSEMBLY","substation_hazus_class":"ESSM","source_assumption_set_id":"FEMA_HAZUS_MH_2_1_TABLE_7_9_UNPROTECTED_SUBSTATION","water_quality_class":"freshwater_non_contaminated","delivered_depth_basis":"unprotected_or_internal_post_bypass_depth","flood_depth_above_substation_grade_ft":4} | D9: conditional | E9: 0.07 | F9: FW_HAZUS_2_1_SUBSTATION_SCREENING_PWL | G9: executed externally | H9: =IF(AND(A9<>"",D9<>"",F9<>""),"PASS","FAIL")
A10: FW_HAZUS_KNOT_05FT | B10: formula | C10: {"pathway_id":"flood_inundation_contact","failure_unit_id":"FW_HAZUS_GSU_SUBSTATION_ASSEMBLY","substation_hazus_class":"ESSH","source_assumption_set_id":"FEMA_HAZUS_MH_2_1_TABLE_7_9_UNPROTECTED_SUBSTATION","water_quality_class":"freshwater_non_contaminated","delivered_depth_basis":"unprotected_or_internal_post_bypass_depth","flood_depth_above_substation_grade_ft":5} | D10: conditional | E10: 0.08 | F10: FW_HAZUS_2_1_SUBSTATION_SCREENING_PWL | G10: executed externally | H10: =IF(AND(A10<>"",D10<>"",F10<>""),"PASS","FAIL")
A11: FW_HAZUS_KNOT_06FT | B11: formula | C11: {"pathway_id":"flood_inundation_contact","failure_unit_id":"FW_HAZUS_GSU_SUBSTATION_ASSEMBLY","substation_hazus_class":"ESSL","source_assumption_set_id":"FEMA_HAZUS_MH_2_1_TABLE_7_9_UNPROTECTED_SUBSTATION","water_quality_class":"freshwater_non_contaminated","delivered_depth_basis":"unprotected_or_internal_post_bypass_depth","flood_depth_above_substation_grade_ft":6} | D11: conditional | E11: 0.09 | F11: FW_HAZUS_2_1_SUBSTATION_SCREENING_PWL | G11: executed externally | H11: =IF(AND(A11<>"",D11<>"",F11<>""),"PASS","FAIL")
A12: FW_HAZUS_KNOT_07FT | B12: formula | C12: {"pathway_id":"flood_inundation_contact","failure_unit_id":"FW_HAZUS_GSU_SUBSTATION_ASSEMBLY","substation_hazus_class":"ESSM","source_assumption_set_id":"FEMA_HAZUS_MH_2_1_TABLE_7_9_UNPROTECTED_SUBSTATION","water_quality_class":"freshwater_non_contaminated","delivered_depth_basis":"unprotected_or_internal_post_bypass_depth","flood_depth_above_substation_grade_ft":7} | D12: conditional | E12: 0.1 | F12: FW_HAZUS_2_1_SUBSTATION_SCREENING_PWL | G12: executed externally | H12: =IF(AND(A12<>"",D12<>"",F12<>""),"PASS","FAIL")
A13: FW_HAZUS_KNOT_08FT | B13: formula | C13: {"pathway_id":"flood_inundation_contact","failure_unit_id":"FW_HAZUS_GSU_SUBSTATION_ASSEMBLY","substation_hazus_class":"ESSH","source_assumption_set_id":"FEMA_HAZUS_MH_2_1_TABLE_7_9_UNPROTECTED_SUBSTATION","water_quality_class":"freshwater_non_contaminated","delivered_depth_basis":"unprotected_or_internal_post_bypass_depth","flood_depth_above_substation_grade_ft":8} | D13: conditional | E13: 0.12 | F13: FW_HAZUS_2_1_SUBSTATION_SCREENING_PWL | G13: executed externally | H13: =IF(AND(A13<>"",D13<>"",F13<>""),"PASS","FAIL")
A14: FW_HAZUS_KNOT_09FT | B14: formula | C14: {"pathway_id":"flood_inundation_contact","failure_unit_id":"FW_HAZUS_GSU_SUBSTATION_ASSEMBLY","substation_hazus_class":"ESSL","source_assumption_set_id":"FEMA_HAZUS_MH_2_1_TABLE_7_9_UNPROTECTED_SUBSTATION","water_quality_class":"freshwater_non_contaminated","delivered_depth_basis":"unprotected_or_internal_post_bypass_depth","flood_depth_above_substation_grade_ft":9} | D14: conditional | E14: 0.14 | F14: FW_HAZUS_2_1_SUBSTATION_SCREENING_PWL | G14: executed externally | H14: =IF(AND(A14<>"",D14<>"",F14<>""),"PASS","FAIL")
A15: FW_HAZUS_KNOT_10FT | B15: formula | C15: {"pathway_id":"flood_inundation_contact","failure_unit_id":"FW_HAZUS_GSU_SUBSTATION_ASSEMBLY","substation_hazus_class":"ESSM","source_assumption_set_id":"FEMA_HAZUS_MH_2_1_TABLE_7_9_UNPROTECTED_SUBSTATION","water_quality_class":"freshwater_non_contaminated","delivered_depth_basis":"unprotected_or_internal_post_bypass_depth","flood_depth_above_substation_grade_ft":10} | D15: conditional | E15: 0.15 | F15: FW_HAZUS_2_1_SUBSTATION_SCREENING_PWL | G15: executed externally | H15: =IF(AND(A15<>"",D15<>"",F15<>""),"PASS","FAIL")
A16: FW_HAZUS_INTERPOLATE_0P5FT | B16: formula | C16: {"pathway_id":"flood_inundation_contact","failure_unit_id":"FW_HAZUS_GSU_SUBSTATION_ASSEMBLY","substation_hazus_class":"ESSL","source_assumption_set_id":"FEMA_HAZUS_MH_2_1_TABLE_7_9_UNPROTECTED_SUBSTATION","water_quality_class":"freshwater_non_contaminated","delivered_depth_basis":"unprotected_or_internal_post_bypass_depth","flood_depth_above_substation_grade_ft":0.5} | D16: conditional | E16: 0.01 | F16: FW_HAZUS_2_1_SUBSTATION_SCREENING_PWL | G16: executed externally | H16: =IF(AND(A16<>"",D16<>"",F16<>""),"PASS","FAIL")
... A19: FW_HAZUS_WSE_BRIDGE_EXACT_1FT | B19: formula | C19: {"pathway_id":"flood_inundation_contact","failure_unit_id":"FW_HAZUS_GSU_SUBSTATION_ASSEMBLY","substation_hazus_class":"ESSH","source_assumption_set_id":"FEMA_HAZUS_MH_2_1_TABLE_7_9_UNPROTECTED_SUBSTATION","water_quality_class":"freshwater_non_contaminated","delivered_depth_basis":"unprotected_or_internal_post_bypass_depth","water_surface_elevation_m":100.3048,"substation_grade_elevation_m":100,"water_surface_vertical_datum_id":"NAVD88","substation_grade_vertical_datum_id":"NAVD88"} | D19: conditional | E19: 0.02 | F19: FW_HAZUS_2_1_SUBSTATION_SCREENING_PWL | G19: executed externally | H19: =IF(AND(A19<>"",D19<>"",F19<>""),"PASS","FAIL")
A20: FW_ABOVE_SOURCE_RANGE_WITHHELD | B20: withheld | C20: {"pathway_id":"flood_inundation_contact","failure_unit_id":"FW_HAZUS_GSU_SUBSTATION_ASSEMBLY","substation_hazus_class":"ESSL","source_assumption_set_id":"FEMA_HAZUS_MH_2_1_TABLE_7_9_UNPROTECTED_SUBSTATION","water_quality_class":"freshwater_non_contaminated","delivered_depth_basis":"unprotected_or_internal_post_bypass_depth","flood_depth_above_substation_grade_ft":10.0001} | D20: withheld | E20: null | F20: ABOVE_SOURCE_VALID_RANGE | G20: executed externally | H20: =IF(AND(A20<>"",D20<>"",F20<>""),"PASS","FAIL")
A21: FW_SALTWATER_WITHHELD | B21: withheld | C21: {"pathway_id":"flood_inundation_contact","failure_unit_id":"FW_HAZUS_GSU_SUBSTATION_ASSEMBLY","substation_hazus_class":"ESSM","source_assumption_set_id":"FEMA_HAZUS_MH_2_1_TABLE_7_9_UNPROTECTED_SUBSTATION","water_quality_class":"saltwater","delivered_depth_basis":"unprotected_or_internal_post_bypass_depth","flood_depth_above_substation_grade_ft":4} | D21: withheld | E21: null | F21: WATER_QUALITY_OUTSIDE_SCREENING_DOMAIN | G21: executed externally | H21: =IF(AND(A21<>"",D21<>"",F21<>""),"PASS","FAIL")
A22: FW_BRACKISH_WITHHELD | B22: withheld | C22: {"pathway_id":"flood_inundation_contact","failure_unit_id":"FW_HAZUS_GSU_SUBSTATION_ASSEMBLY","substation_hazus_class":"ESSM","source_assumption_set_id":"FEMA_HAZUS_MH_2_1_TABLE_7_9_UNPROTECTED_SUBSTATION","water_quality_class":"brackish","delivered_depth_basis":"unprotected_or_internal_post_bypass_depth","flood_depth_above_substation_grade_ft":4} | D22: withheld | E22: null | F22: WATER_QUALITY_OUTSIDE_SCREENING_DOMAIN | G22: executed externally | H22: =IF(AND(A22<>"",D22<>"",F22<>""),"PASS","FAIL")
A23: FW_CONTAMINATED_WITHHELD | B23: withheld | C23: {"pathway_id":"flood_inundation_contact","failure_unit_id":"FW_HAZUS_GSU_SUBSTATION_ASSEMBLY","substation_hazus_class":"ESSM","source_assumption_set_id":"FEMA_HAZUS_MH_2_1_TABLE_7_9_UNPROTECTED_SUBSTATION","water_quality_class":"freshwater_contaminated","delivered_depth_basis":"unprotected_or_internal_post_bypass_depth","flood_depth_above_substation_grade_ft":4} | D23: withheld | E23: null | F23: WATER_QUALITY_OUTSIDE_SCREENING_DOMAIN | G23: executed externally | H23: =IF(AND(A23<>"",D23<>"",F23<>""),"PASS","FAIL")
A24: FW_UNKNOWN_WATER_WITHHELD | B24: withheld | C24: {"pathway_id":"flood_inundation_contact","failure_unit_id":"FW_HAZUS_GSU_SUBSTATION_ASSEMBLY","substation_hazus_class":"ESSM","source_assumption_set_id":"FEMA_HAZUS_MH_2_1_TABLE_7_9_UNPROTECTED_SUBSTATION","water_quality_class":"unknown","delivered_depth_basis":"unprotected_or_internal_post_bypass_depth","flood_depth_above_substation_grade_ft":4} | D24: withheld | E24: null | F24: WATER_QUALITY_OUTSIDE_SCREENING_DOMAIN | G24: executed externally | H24: =IF(AND(A24<>"",D24<>"",F24<>""),"PASS","FAIL")
A25: FW_COMPONENT_UNIT_WITHHELD_NOT_ZERO | B25: withheld | C25: {"pathway_id":"flood_inundation_contact","failure_unit_id":"FW_GSU_TRANSFORMER_MAIN","substation_hazus_class":"ESSH","source_assumption_set_id":"FEMA_HAZUS_MH_2_1_TABLE_7_9_UNPROTECTED_SUBSTATION","water_quality_class":"freshwater_non_contaminated","delivered_depth_basis":"unprotected_or_internal_post_bypass_depth","flood_depth_above_substation_grade_ft":5} | D25: withheld | E25: null | F25: NO_RUNTIME_CURVE_FOR_PATHWAY_UNIT | G25: executed externally | H25: =IF(AND(A25<>"",D25<>"",F25<>""),"PASS","FAIL")
A26: FW_PATHWAY_REQUIRED | B26: error | C26: {} | D26: rejected | E26: null | F26: PATHWAY_ID_REQUIRED | G26: executed externally | H26: =IF(AND(A26<>"",D26<>"",F26<>""),"PASS","FAIL")
A27: FW_PATHWAY_UNKNOWN | B27: error | C27: {"pathway_id":"flood"} | D27: rejected | E27: null | F27: PATHWAY_ID_UNKNOWN | G27: executed externally | H27: =IF(AND(A27<>"",D27<>"",F27<>""),"PASS","FAIL")
A28: FW_CLASS_REQUIRED | B28: error | C28: {"pathway_id":"flood_inundation_contact"} | D28: rejected | E28: null | F28: SUBSTATION_HAZUS_CLASS_REQUIRED | G28: executed externally | H28: =IF(AND(A28<>"",D28<>"",F28<>""),"PASS","FAIL")
A29: FW_CLASS_UNSUPPORTED | B29: error | C29: {"pathway_id":"flood_inundation_contact","substation_hazus_class":"SUBSTATION"} | D29: rejected | E29: null | F29: SUBSTATION_HAZUS_CLASS_UNSUPPORTED | G29: executed externally | H29: =IF(AND(A29<>"",D29<>"",F29<>""),"PASS","FAIL")
A30: FW_ASSUMPTION_REQUIRED | B30: error | C30: {"pathway_id":"flood_inundation_contact","substation_hazus_class":"ESSL"} | D30: rejected | E30: null | F30: SOURCE_ASSUMPTION_SET_REQUIRED | G30: executed externally | H30: =IF(AND(A30<>"",D30<>"",F30<>""),"PASS","FAIL")
A31: FW_ASSUMPTION_UNSUPPORTED | B31: error | C31: {"pathway_id":"flood_inundation_contact","substation_hazus_class":"ESSL","source_assumption_set_id":"GENERIC"} | D31: rejected | E31: null | F31: SOURCE_ASSUMPTION_SET_UNSUPPORTED | G31: executed externally | H31: =IF(AND(A31<>"",D31<>"",F31<>""),"PASS","FAIL")
... A41: FW_UNKNOWN_FAILURE_UNIT | B41: error | C41: {"pathway_id":"flood_inundation_contact","failure_unit_id":"WIND_FARM","substation_hazus_class":"ESSL","source_assumption_set_id":"FEMA_HAZUS_MH_2_1_TABLE_7_9_UNPROTECTED_SUBSTATION","water_quality_class":"freshwater_non_contaminated","delivered_depth_basis":"unprotected_or_internal_post_bypass_depth","flood_depth_above_substation_grade_ft":2} | D41: rejected | E41: null | F41: FAILURE_UNIT_ID_UNKNOWN | G41: executed externally | H41: =IF(AND(A41<>"",D41<>"",F41<>""),"PASS","FAIL")

Sheet Source_Register
A1: Source register
A2: Every source has a locator plus permitted and prohibited inference
A4: Source ID | B4: Citation | C4: URL/path | D4: Locator | E4: Role | F4: Tier | G4: Endpoint | H4: Permitted | I4: Prohibited | J4: Decision | K4: Status | L4: Notes
A5: FW-S001 | B5: Federal Energy Regulatory Commission, Order on accounting for renewable generating assets, 174 FERC 61,033 (2021). | C5: https://www.ferc.gov/sites/default/files/2021-01/E-7-011921.pdf | D5: pp. 2-3, wind items a-e and solar items a-g | E5: asset_anatomy | F5: T2_public_lab_standard_or_physics | G5: typical wind and solar collection buses and high-voltage Plant GSU configuration | H5: Define common Plant-GSU/substation anatomy across solar and wind. | I5: Infer flood vulnerability, component value, ownership, quantity, or a universal site configuration. | J5: adopt_with_limits | K5: reviewed | L5: Both technologies use a facility-substation collection bus and Plant GSU; upstream equipment remains technology-specific.
A6: FW-S002 | B6: National Electrical Manufacturers Association, NEMA GD 1-2016, Evaluating Water-Damaged Electrical Equipment (historical edition). | C6: https://www.nema.org/docs/default-source/secure-document-library/nema-gd-1-2016-evaluating-water-damaged-electrical-equipment-guide.pdf | D6: sections 4.3 Power Equipment and 4.4 Transformers | E6: historical_mechanism_and_disposition | F6: T2_public_lab_standard_or_physics | G6: historical water-exposed switchgear/power-equipment and transformer evaluation reconditioning/replacement considerations | H6: Retain historical equipment-family and mechanism context while the 2026 successor is acquired and reviewed. | I6: Treat the 2016 edition as current guidance, derive continuous depth-DR ordinates, or override current OEM/manufacturer guidance. | J6: retain_historical_pending_successor_review | K6: historical_superseded | L6: NEMA's April 2026 publication register lists the same-titled successor guide NEMA CS 70006-2026; see FW-S013. Historical content does not calibrate the FEMA knots.
A7: FW-S003 | B7: North American Electric Reliability Corporation, Substation Flooding Events Highlight Potential Design Deficiencies (2022). | C7: https://www.nerc.com/pa/rrm/ea/Lessons%20Learned%20Document%20Library/LL20220404_Substation_Flooding_Events_Highlight_Potential_Design_Deficiencies.pdf | D7: p. 1, approximately 8 inches at 250 VDC control connections and resulting operations | E7: case_study_severity | F7: T3_engineering_proxy_or_adjacent_empirical | G7: one relay-room flood case causing false breaker operations and removal of two circuits and six generating units | H7: Confirm shallow control/protection inundation can be operationally material and motivate separate control/DC units. | I7: Treat 495 MW removed from service as direct physical DR or repair cost. | J7: adopt_with_limits | K7: reviewed | L7: Operational consequence is downstream; no same-unit cost endpoint.
A8: FW-S004 | B8: North American Electric Reliability Corporation, Severe Flooding Damages Transformer Substations (2015). | C8: https://www.nerc.com/pa/rrm/ea/Lessons%20Learned%20Document%20Library/LL20150402_Severe_Flooding_Damages_Transformer_Substations_final.pdf | D8: problem statement, details, and corrective actions | E8: case_study_severity | F8: T3_engineering_proxy_or_adjacent_empirical | G8: telecommunication protection and station-service damage and circuit unavailability at two substations | H8: Support component decomposition and water-path/elevation fields. | I8: Fit an economic damage curve or infer renewable-project ownership/value. | J8: adopt_with_limits | K8: reviewed | L8: Transmission-station case; mechanism transfer only.
A9: FW-S005 | B9: Federal Emergency Management Agency, FEMA P-348, Protecting Building Utility Systems From Flood Damage, 2nd ed. (2017). | C9: https://www.fema.gov/sites/default/files/2020-07/fema_p-348_protecting_building_utility_systems_from_flood_damage_2017.pdf | D9: section 5.2, electrical-system flood risk and mitigation | E9: axis_and_exposure | F9: T2_public_lab_standard_or_physics | G9: elevation/relocation/protection of transformers switchboards panels and feeders | H9: Support local vulnerable datum and equipment-elevation fields. | I9: Provide wind-farm ordinates or replacement percentages. | J9: adopt_with_limits | K9: reviewed | L9: Building-utility setting; used for method, not calibration.
A10: FW-S006 | B10: U.S. Army Corps of Engineers, HEC-FIA Technical Reference, Depth-Percent Damage Relationships. | C10: https://www.hec.usace.army.mil/confluence/fiadocs/fiatechref/latest/direct-damage/depth-percent-damage-relationships-direct-damage | D10: direct damage, depth-percent relationship and linear interpolation | E10: curve_form | F10: T2_public_lab_standard_or_physics | G10: tabular depth-percent relationship and interpolation method | H10: Support transparent piecewise/tabular curve form and critical-elevation semantics. | I10: Supply electrical-component ordinates. | J10: adopt_with_limits | K10: reviewed | L10: Form precedent only.
A11: FW-S007 | B11: U.S. Department of Energy FEMP, Preventing and Mitigating Flood Damage to Solar Photovoltaic Systems. | C11: https://www.energy.gov/cmei/femp/preventing-and-mitigating-flood-damage-solar-photovoltaic-systems | D11: total submersion, equipment elevation, conduit-water pathway, and electrical enclosure sections | E11: mechanism_and_exposure | F11: T2_public_lab_standard_or_physics | G11: solar-site observations and guidance for submerged electrical equipment and conduit water transport | H11: Support shared electrical water-path/elevation concepts where equipment matches. | I11: Infer wind-specific values or universal numeric curves. | J11: adopt_with_limits | K11: reviewed | L11: Solar-specific adjacent source; no wind curve.
A12: FW-S008 | B12: Stehly, T.; Duffy, P.; Mulas Hernando, D. Cost of Wind Energy Review: 2024 Edition. NREL/TP-5000-91775. | C12: https://www.nrel.gov/docs/fy25osti/91775.pdf | D12: land-based reference plant capital-cost breakdown | E12: exposure_or_value | F12: T2_public_lab_standard_or_physics | G12: 2023-USD wind component and balance-of-system reference values | H12: Use the row-level reference ledger and identify the mixed 72 USD/kW electrical bucket. | I12: Infer a 9% substation share, fragility, ownership, or site replacement value. | J12: adopt_with_limits | K12: reviewed | L12: Value archetype only; substation and collection are not split.
A13: FW-S009 | B13: Federal Energy Regulatory Commission, pro forma Large Generator Interconnection Agreement. | C13: https://www.ferc.gov/sites/default/files/2020-04/LGIA.pdf | D13: definitions of Point of Change of Ownership and Point of Interconnection; Appendix A dependency | E13: ownership_boundary | F13: T2_public_lab_standard_or_physics | G13: contract-defined ownership/interconnection demarcations | H13: Require site agreement/one-line evidence for project versus transmission-owner inclusion. | I13: Assume ownership from physical role or map proximity. | J13: adopt_with_limits | K13: reviewed | L13: Template establishes that demarcation is agreement-specific.
A14: FW-S010 | B14: Canonical Damage Modeling flood_solar artifact, flood_solar@model_v1_0__docs_r4. | C14: docs/cells/flood_solar/current/flood_solar__model_v1_0__docs_r4__curve_artifact.json | D14: FS_SWG, FS_XFMR, FS_SCADA, FS_CABLE; artifact SHA a08e77ef034e1ecea3e7cd05d13c825921b54d610fca9de8651ebda8e857082d | E14: candidate_curve_and_method | F14: T3_engineering_proxy_or_adjacent_empirical | G14: deterministic T3 electrical depth-damage records and T2 local-datum transform | H14: Reuse axis/method and retain exact ordinates as pinned audit candidates under explicit crosswalk. | I14: Silently copy numerics into flood_wind or call them claims-calibrated asset-neutral curves. | J14: defer_candidate_only | K14: reviewed | L14: Canonical inside flood_solar; not runtime-approved for flood_wind.
A15: FW-S011 | B15: Federal Emergency Management Agency, Hazus-MH Flood Model Technical Manual, version 2.1. | C15: https://www.fema.gov/sites/default/files/2020-09/fema_hazus_flood-model_technical-manual_2.1.pdf | D15: sections 7.2.2, 7.2.4, and 7.2.6; Table 7.9, pp. 7-20 through 7-21; Table 7.9 footnote 2 and comments | E15: source_native_curve_and_assumptions | F15: T3_engineering_proxy_or_adjacent_empirical | G15: modeled whole-electric-substation depth-percent-damage values for ESSL ESSM and ESSH from 0 through 10 ft | H15: Reproduce the exact whole-substation source table as a strictly gated legacy screening curve and preserve its source assumptions. | I15: Infer component curves, field or claims calibration, wind-farm TIV loss, saline-water applicability, protection credit, or current Hazus enablement. | J15: adopt_screening_with_strict_gate | K15: reviewed | L15: Official source-native table; source PDF SHA-256 476726f194ed7e0702e8d6b47ad62616c8ca78214e56e9efc848f3bd547ae669. Section 7.2.4 also says electric-power implementation was deferred.
... A22: BOUNDED_SEARCH_LOG | B22: Bounded evidence search log for flood_wind model v0.1/docs r1. | C22: docs/cells/flood_wind/current/BOUNDED_EVIDENCE_SEARCH_LOG_flood_wind__model_v0_1__docs_r1.md | D22: search surfaces endpoint tests limitations and refresh triggers | E22: historical_negative_evidence_boundary | F22: T3_engineering_proxy_or_adjacent_empirical | G22: historical bounded result that no public matched component-local depth/state-to-disposition-to-same-unit-cost chain was located | H22: Retain the component-level negative boundary and document why the whole-substation source reopens only a different grain. | I22: Repeat the old conclusion as universal across whole-substation functions, private evidence, non-English evidence, unindexed evidence, or later publications. | J22: partially_superseded_by_FW-S011 | K22: reviewed | L22: Still governing for component-level records; superseded only at the whole-substation source atom by FW-S011 and constrained by FW-S012.

Sheet Claim_Register
A1: Claim register
A2: No load-bearing claim is allowed to outrun its source
A4: Claim ID | B4: Claim | C4: Type | D4: Source IDs | E4: Locator | F4: Tier | G4: Rule | H4: Status | I4: Permitted | J4: Prohibited | K4: Reasoning | L4: Update trigger
